Workbook

Sheet Overview
A1: Emigrant Wilderness — Big Sam Loop Crew Meal Plan (19 People)
A2: July 25–30, 2026 · Kennedy Meadows Loop · ~46.9 mi · 13 Scouts · 6 Adults | 3 Scout cans (3 people) · 1 Scout can (4 people) · 2 Adult cans (3 people)
A4: BEAR CAN STRUCTURE
A5: Can assignment | B5: Can 1 | C5: Can 2 | D5: Can 3 | E5: Can 4 | F5: Can 5 | G5: Can 6 | H5: Type | I5: People | J5: Notes
A6: Can assignment | B6: Scout Can 1 | C6: Scout Can 2 | D6: Scout Can 3 | E6: Scout Can 4 | F6: Adult Can 1 | G6: Adult Can 2 | J6: 4 scout cans + 2 adult cans
A7: People per can | B7: 3 scouts | C7: 3 scouts | D7: 3 scouts | E7: 4 scouts | F7: 3 adults | G7: 3 adults | J7: Scouts: 3, 3, 3, 4 · Adults: 3, 3
A8: Hot drink | B8: Swiss Miss | C8: Swiss Miss | D8: Swiss Miss | E8: Swiss Miss | F8: own coffee | G8: own coffee | J8: Scouts: Swiss Miss · Adults: own coffee/tea
A9: Carry capacity | B9: 3 Days | C9: 3 Days | D9: 3 Days | E9: 3 Days | F9: 3 Days | G9: 3 Days | J9: Balance food is mule dropped (Days 4–6)
A11: TRIP SCHEDULE
A12: Day | B12: Date | C12: Route | D12: Miles | E12: Gain | F12: Loss | G12: Camp | H12: Meals | I12: Water | J12: Notes
A13: Day 1 | B13: Sat Jul 25 | C13: Kennedy Meadows → Lower Relief Valley | D13: 6.88 mi | E13: +2,262 ft | F13: −579 ft | G13: Lower Relief Valley | H13: Snacks · Lunch · Dinner · Dessert | I13: Reservoir/Creek (filter) | J13: morale swimming hole side-trip
A14: Day 2 | B14: Sun Jul 26 | C14: Lower Relief Valley → Spring Meadow | D14: 5.97 mi | E14: +1,129 ft | F14: −509 ft | G14: Spring Meadow | H14: Bkfst · Snacks · Lunch · Dinner · Dessert | I14: Spring/Creek (filter) | J14: Wire Lake side-trip
A15: Day 3 | B15: Mon Jul 27 | C15: Spring Meadow → eastern Emigrant Lake | D15: 8.89 mi | E15: +1,210 ft | F15: −1,035 ft | G15: Emigrant Lake (east) | H15: Bkfst · Snacks · Lunch · Dinner · Dessert | I15: Lake (filter) | J15: morale swimming spot; Buck Lake on route
A16: Day 4 | B16: Tue Jul 28 | C16: Emigrant Lake → Grizzly Peak Base Camp | D16: 6.59 mi | E16: +1,575 ft | F16: −742 ft | G16: Grizzly Peak Base Camp | H16: Bkfst · Snacks · Lunch · Dinner · Dessert | I16: Lake (filter) | J16: Mule drop refilled; cooler alpine camp
A17: Day 5 | B17: Wed Jul 29 | C17: Grizzly Peak → Big Sam → Kennedy Lake | D17: 8.46 mi | E17: +1,428 ft | F17: −3,238 ft | G17: South Kennedy Lake | H17: Bkfst · Snacks · Lunch · Dinner · Dessert | I17: Creek (filter) | J17: Climb Big Sam (10,804 ft); long descent
A18: Day 6 | B18: Thu Jul 30 | C18: Kennedy Lake → Kennedy Meadows (Exit) | D18: 8.50 mi | E18: +0 ft | F18: −1,517 ft | G18: Exit — Trailhead | H18: Bkfst · Snacks · Lunch | I18: Creek/Tap | J18: Walk out valley; celebrate at trailhead
A19: TOTALS | D19: 51.29 mi | E19: +7,604 ft | F19: −8,620 ft | J19: Totals include optional side-trips
A21: CALORIE OVERVIEW (per person)
B22: Scouts | C22: Adults | D22: Notes
A23: Target (full active day) | B23: ~2,750 kcal | C23: ~3,750 kcal | D23: Target calorie values
A24: Sat Jul 25 delivered | B24: ='Meal Plan (Per Bear Can)'!F31 | C24: ='Meal Plan (Per Bear Can)'!H31 | D24: Snacks + Lunch + Dinner + Dessert (no breakfast carried)
A25: Sun Jul 26 delivered | B25: ='Meal Plan (Per Bear Can)'!F72 | C25: ='Meal Plan (Per Bear Can)'!H72 | D25: Bkfst + Snacks + Lunch + Dinner + Dessert + Adult Supp
A26: Mon Jul 27 delivered | B26: ='Meal Plan (Per Bear Can)'!F108 | C26: ='Meal Plan (Per Bear Can)'!H108 | D26: Bkfst + Snacks + Lunch + Dinner + Dessert
A27: Tue Jul 28 delivered | B27: ='Meal Plan (Per Bear Can)'!F144 | C27: ='Meal Plan (Per Bear Can)'!H144 | D27: Bkfst + Snacks + Lunch + Dinner + Dessert
A28: Wed Jul 29 delivered | B28: ='Meal Plan (Per Bear Can)'!F186 | C28: ='Meal Plan (Per Bear Can)'!H186 | D28: Bkfst + Snacks + Lunch + Dinner + Dessert + Adult Supp
A29: Thu Jul 30 delivered | B29: ='Meal Plan (Per Bear Can)'!F210 | C29: ='Meal Plan (Per Bear Can)'!H210 | D29: Bkfst + Snacks + Lunch (exit day; no dinner)
A30: TRIP TOTAL (6 DAYS) | B30: ='Meal Plan (Per Bear Can)'!F215 | C30: ='Meal Plan (Per Bear Can)'!H215 | D30: Total food purchased per person across all 6 days
A31: MAX CARRY WEIGHT VOL (3 DAYS) | B31: =MAX('Meal Plan (Per Bear Can)'!F110,'Meal Plan (Per Bear Can)'!F212) | C31: =MAX('Meal Plan (Per Bear Can)'!H110,'Meal Plan (Per Bear Can)'!H212) | D31: Maximum food carried at one time in canisters
A33: BUDGET & WEIGHT OVERVIEW (6 Days Purchased / 3 Days Carried)
B34: Adult Can (3 ppl) (×2) | C34: Scout Can (3 ppl) (×3) | D34: Scout Can (4 ppl) (×1) | E34: Group Total | F34: Notes
A35: Estimated Purchased Cost (6 days) | B35: =SUM('Shopping List'!M$4:M$32) | C35: =SUM('Shopping List'!K$4:K$32) | D35: =SUM('Shopping List'!L$4:L$32) | E35: =SUM('Shopping List'!N$4:N$32) | F35: Full 6 days food cost; bulk prices
A36: Per person cost | B36: =B35/3 | C36: =C35/3 | D36: =D35/4 | E36: =E35/19 | F36: Averaged across group
A37: Max Carry Weight (3 days) | B37: =SUMPRODUCT('Shopping List'!E$4:E$32,'Shopping List'!O$4:O$32)/16 | C37: =SUMPRODUCT('Shopping List'!C$4:C$32,'Shopping List'!O$4:O$32)/16 | D37: =SUMPRODUCT('Shopping List'!D$4:D$32,'Shopping List'!O$4:O$32)/16 | E37: =SUMPRODUCT(3*'Shopping List'!C$4:C$32+1*'Shopping List'!D$4:D$32+2*'Shopping List'!E$4:E$32,'Shopping List'!O$4:O$32)/16 | F37: Max carried weight in lbs (Phase 1)
A38: Mule Drop Weight (3 days) | B38: =SUMPRODUCT('Shopping List'!H$4:H$32,'Shopping List'!O$4:O$32)/16 | C38: =SUMPRODUCT('Shopping List'!F$4:F$32,'Shopping List'!O$4:O$32)/16 | D38: =SUMPRODUCT('Shopping List'!G$4:G$32,'Shopping List'!O$4:O$32)/16 | E38: =SUMPRODUCT(3*'Shopping List'!F$4:F$32+1*'Shopping List'!G$4:G$32+2*'Shopping List'!H$4:H$32,'Shopping List'!O$4:O$32)/16 | F38: Mule drop weight in lbs (Phase 2)
A40: WATER & SAFETY INFORMATION
A41: Location | B41: Source | C41: Reliability | D41: Required Action
A42: Kennedy Meadows Trailhead | B42: Pack Station tap | C42: Reliable | D42: Fill all bottles. Carry 2-3 L per person.
A43: Relief Reservoir | B43: Reservoir outlet | C43: Reliable | D43: morale boost lunch stop. Filter all water.
A44: Lower Relief Valley Camp | B44: Creek / Spring | C44: Reliable | D44: morale swimming spot side trip nearby.
A45: Spring Meadow Camp | B45: Meadow stream | C45: Reliable | D45: morale boost meadow camp. Filter water.
...

Sheet Meal Plan (Per Bear Can)
A1: Meal Plan — Quantities & Nutritional Breakdown Per Bear Can Type
A2: Calculated for: Scout Can (3 people), Scout Can (4 people), and Adult Can (3 people) | ⚠ Highlighted = Contains Nuts (swap for allergy scout)
A4: PHASE 1 — INITIAL CARRY (DAYS 1–3)
A5: SAT JUL 25 — DAY 1 DETAILS
A6: Sat Jul 25 — BREAKFAST (✗ NOT CARRIED — eat before leaving trailhead)
A7: Sat Jul 25 — SNACKS
A8: Food Item | B8: Qty (Scout 3) | C8: Qty (Scout 4) | D8: Qty (Adult 3) | E8: kcal/unit | F8: Scout 3 kcal | G8: Scout 4 kcal | H8: Adult 3 kcal | I8: $/unit | J8: Scout 3 $ | K8: Scout 4 $ | L8: Adult 3 $ | M8: oz/unit | N8: Scout 3 oz | O8: Scout 4 oz | P8: Adult 3 oz | Q8: Notes
A9: Kind – Peanut Butter Dark Chocolate Bar | B9: 3 | C9: 4 | D9: 3 | E9: 200 | F9: =B9*E9 | G9: =C9*E9 | H9: =D9*E9 | I9: 1.04 | J9: =B9*I9 | K9: =C9*I9 | L9: =D9*I9 | M9: 1.4 | N9: =B9*M9 | O9: =C9*M9 | P9: =D9*M9 | Q9: ⚠ NUT: swap → 88 Acres bar
A10: Kind – Caramel Almond & Peanut Bar | B10: 3 | C10: 4 | D10: 3 | E10: 180 | F10: =B10*E10 | G10: =C10*E10 | H10: =D10*E10 | I10: 1.59 | J10: =B10*I10 | K10: =C10*I10 | L10: =D10*I10 | M10: 1.4 | N10: =B10*M10 | O10: =C10*M10 | P10: =D10*M10 | Q10: ⚠ NUT: swap → 88 Acres bar
A11: Krave Sea Salt Original Beef Jerky | B11: 3 | C11: 4 | D11: 3 | E11: 140 | F11: =B11*E11 | G11: =C11*E11 | H11: =D11*E11 | I11: 2.19 | J11: =B11*I11 | K11: =C11*I11 | L11: =D11*I11 | M11: 1.48 | N11: =B11*M11 | O11: =C11*M11 | P11: =D11*M11 | Q11: Safe for nut allergy ✓
A12: Gatorade Powder Pack | B12: 3 | C12: 4 | D12: 3 | E12: 130 | F12: =B12*E12 | G12: =C12*E12 | H12: =D12*E12 | I12: 0.38 | J12: =B12*I12 | K12: =C12*I12 | L12: =D12*I12 | M12: 1.23 | N12: =B12*M12 | O12: =C12*M12 | P12: =D12*M12 | Q12: Electrolytes
A13: Trader Joe's Dried Mango Slices (1 oz) | B13: 3 | C13: 4 | D13: 3 | E13: 90 | F13: =B13*E13 | G13: =C13*E13 | H13: =D13*E13 | I13: 0.55 | J13: =B13*I13 | K13: =C13*I13 | L13: =D13*I13 | M13: 1 | N13: =B13*M13 | O13: =C13*M13 | P13: =D13*M13 | Q13: TJ's — Sat snack · nut-free ✓
A14: SNACKS Total | F14: =SUM(F9:F13) | G14: =SUM(G9:G13) | H14: =SUM(H9:H13) | J14: =SUM(J9:J13) | K14: =SUM(K9:K13) | L14: =SUM(L9:L13) | N14: =SUM(N9:N13) | O14: =SUM(O9:O13) | P14: =SUM(P9:P13)
A15: Sat Jul 25 — LUNCH
A16: Food Item | B16: Qty (Scout 3) | C16: Qty (Scout 4) | D16: Qty (Adult 3) | E16: kcal/unit | F16: Scout 3 kcal | G16: Scout 4 kcal | H16: Adult 3 kcal | I16: $/unit | J16: Scout 3 $ | K16: Scout 4 $ | L16: Adult 3 $ | M16: oz/unit | N16: Scout 3 oz | O16: Scout 4 oz | P16: Adult 3 oz | Q16: Notes
A17: ProBar Meal – Oatmeal Chocolate Chip | B17: 3 | C17: 4 | D17: 3 | E17: 290 | F17: =B17*E17 | G17: =C17*E17 | H17: =D17*E17 | I17: 2.99 | J17: =B17*I17 | K17: =C17*I17 | L17: =D17*I17 | M17: 3 | N17: =B17*M17 | O17: =C17*M17 | P17: =D17*M17 | Q17: Lunch · ⚠ NUT (cashews)
A18: LUNCH Total | F18: =SUM(F17:F17) | G18: =SUM(G17:G17) | H18: =SUM(H17:H17) | J18: =SUM(J17:J17) | K18: =SUM(K17:K17) | L18: =SUM(L17:L17) | N18: =SUM(N17:N17) | O18: =SUM(O17:O17) | P18: =SUM(P17:P17)
A19: Sat Jul 25 — DINNER
A20: Food Item | B20: Qty (Scout 3) | C20: Qty (Scout 4) | D20: Qty (Adult 3) | E20: kcal/unit | F20: Scout 3 kcal | G20: Scout 4 kcal | H20: Adult 3 kcal | I20: $/unit | J20: Scout 3 $ | K20: Scout 4 $ | L20: Adult 3 $ | M20: oz/unit | N20: Scout 3 oz | O20: Scout 4 oz | P20: Adult 3 oz | Q20: Notes
A21: Peak Refuel – Beef Pasta Marinara | B21: 2 | C21: 3 | D21: 3 | E21: 780 | F21: =B21*E21 | G21: =C21*E21 | H21: =D21*E21 | I21: 7.49 | J21: =B21*I21 | K21: =C21*I21 | L21: =D21*I21 | M21: 3.2 | N21: =B21*M21 | O21: =C21*M21 | P21: =D21*M21 | Q21: Sat dinner (1.5 svgs/pouch)
A22: Mission Street Taco Flour Tortillas | B22: 6 | C22: 8 | D22: 6 | E22: 75 | F22: =B22*E22 | G22: =C22*E22 | H22: =D22*E22 | I22: 0.25 | J22: =B22*I22 | K22: =C22*I22 | L22: =D22*I22 | M22: 0.5 | N22: =B22*M22 | O22: =C22*M22 | P22: =D22*M22 | Q22: 2/person; nut-free ✓
A23: Tillamook Cheddar Cheese Packets | B23: 6 | C23: 8 | D23: 6 | E23: 90 | F23: =B23*E23 | G23: =C23*E23 | H23: =D23*E23 | I23: 0.75 | J23: =B23*I23 | K23: =C23*I23 | L23: =D23*I23 | M23: 0.7 | N23: =B23*M23 | O23: =C23*M23 | P23: =D23*M23 | Q23: 2/person; nut-free ✓
A24: Swiss Miss Hot Chocolate | B24: 6 | C24: 8 | D24: 0 | E24: 90 | F24: =B24*E24 | G24: =C24*E24 | H24: =D24*E24 | I24: 0.38 | J24: =B24*I24 | K24: =C24*I24 | L24: =D24*I24 | M24: 0.73 | N24: =B24*M24 | O24: =C24*M24 | P24: =D24*M24 | Q24: Scouts only (2 packets/person)
A25: DINNER Total | F25: =SUM(F21:F24) | G25: =SUM(G21:G24) | H25: =SUM(H21:H24) | J25: =SUM(J21:J24) | K25: =SUM(K21:K24) | L25: =SUM(L21:L24) | N25: =SUM(N21:N24) | O25: =SUM(O21:O24) | P25: =SUM(P21:P24)
A26: Sat Jul 25 — DESSERT
A27: Food Item | B27: Qty (Scout 3) | C27: Qty (Scout 4) | D27: Qty (Adult 3) | E27: kcal/unit | F27: Scout 3 kcal | G27: Scout 4 kcal | H27: Adult 3 kcal | I27: $/unit | J27: Scout 3 $ | K27: Scout 4 $ | L27: Adult 3 $ | M27: oz/unit | N27: Scout 3 oz | O27: Scout 4 oz | P27: Adult 3 oz | Q27: Notes
A28: Backpacker's Pantry – Crème Brûlée | B28: 2 | C28: 2 | D28: 2 | E28: 620 | F28: =B28*E28 | G28: =C28*E28 | H28: =D28*E28 | I28: 8.99 | J28: =B28*I28 | K28: =C28*I28 | L28: =D28*I28 | M28: 2.26 | N28: =B28*M28 | O28: =C28*M28 | P28: =D28*M28 | Q28: Buddy-pair shares pouch
A29: Swiss Miss Hot Chocolate | B29: 6 | C29: 8 | D29: 0 | E29: 90 | F29: =B29*E29 | G29: =C29*E29 | H29: =D29*E29 | I29: 0.38 | J29: =B29*I29 | K29: =C29*I29 | L29: =D29*I29 | M29: 0.73 | N29: =B29*M29 | O29: =C29*M29 | P29: =D29*M29 | Q29: Scouts only (2 packets/person)
A30: DESSERT Total | F30: =SUM(F28:F29) | G30: =SUM(G28:G29) | H30: =SUM(H28:H29) | J30: =SUM(J28:J29) | K30: =SUM(K28:K29) | L30: =SUM(L28:L29) | N30: =SUM(N28:N29) | O30: =SUM(O28:O29) | P30: =SUM(P28:P29)
A31: DAY 1 (Sat Jul 25) TOTAL | F31: =SUM(F14,F18,F25,F30) | G31: =SUM(G14,G18,G25,G30) | H31: =SUM(H14,H18,H25,H30) | J31: =SUM(J14,J18,J25,J30) | K31: =SUM(K14,K18,K25,K30) | L31: =SUM(L14,L18,L25,L30) | N31: =SUM(N14,N18,N25,N30) | O31: =SUM(O14,O18,O25,O30) | P31: =SUM(P14,P18,P25,P30)
A33: SUN JUL 26 — DAY 2 DETAILS
A34: Sun Jul 26 — BREAKFAST
A35: Food Item | B35: Qty (Scout 3) | C35: Qty (Scout 4) | D35: Qty (Adult 3) | E35: kcal/unit | F35: Scout 3 kcal | G35: Scout 4 kcal | H35: Adult 3 kcal | I35: $/unit | J35: Scout 3 $ | K35: Scout 4 $ | L35: Adult 3 $ | M35: oz/unit | N35: Scout 3 oz | O35: Scout 4 oz | P35: Adult 3 oz | Q35: Notes
A36: MET-Rx Big100 – Super Cookie Crunch | B36: 3 | C36: 4 | D36: 3 | E36: 410 | F36: =B36*E36 | G36: =C36*E36 | H36: =D36*E36 | I36: 2.19 | J36: =B36*I36 | K36: =C36*I36 | L36: =D36*I36 | M36: 3.53 | N36: =B36*M36 | O36: =C36*M36 | P36: =D36*M36 | Q36: Bkfst · ⚠ NUT
A37: Swiss Miss Hot Chocolate | B37: 6 | C37: 8 | D37: 0 | E37: 90 | F37: =B37*E37 | G37: =C37*E37 | H37: =D37*E37 | I37: 0.38 | J37: =B37*I37 | K37: =C37*I37 | L37: =D37*I37 | M37: 0.73 | N37: =B37*M37 | O37: =C37*M37 | P37: =D37*M37 | Q37: Scouts only (2 packets/person)
A38: Adults: own coffee / tea | B38: 0 | C38: 0 | D38: 3 | E38: 0 | F38: =B38*E38 | G38: =C38*E38 | H38: =D38*E38 | I38: 0 | J38: =B38*I38 | K38: =C38*I38 | L38: =D38*I38 | M38: 0 | N38: =B38*M38 | O38: =C38*M38 | P38: =D38*M38 | Q38: Adults only ★
A39: BREAKFAST Total | F39: =SUM(F36:F38) | G39: =SUM(G36:G38) | H39: =SUM(H36:H38) | J39: =SUM(J36:J38) | K39: =SUM(K36:K38) | L39: =SUM(L36:L38) | N39: =SUM(N36:N38) | O39: =SUM(O36:O38) | P39: =SUM(P36:P38)
A40: Sun Jul 26 — SNACKS
A41: Food Item | B41: Qty (Scout 3) | C41: Qty (Scout 4) | D41: Qty (Adult 3) | E41: kcal/unit | F41: Scout 3 kcal | G41: Scout 4 kcal | H41: Adult 3 kcal | I41: $/unit | J41: Scout 3 $ | K41: Scout 4 $ | L41: Adult 3 $ | M41: oz/unit | N41: Scout 3 oz | O41: Scout 4 oz | P41: Adult 3 oz | Q41: Notes
A42: Krave Sea Salt Original Beef Jerky | B42: 3 | C42: 4 | D42: 3 | E42: 140 | F42: =B42*E42 | G42: =C42*E42 | H42: =D42*E42 | I42: 2.19 | J42: =B42*I42 | K42: =C42*I42 | L42: =D42*I42 | M42: 1.48 | N42: =B42*M42 | O42: =C42*M42 | P42: =D42*M42 | Q42: Safe for nut allergy ✓
...

Sheet Shopping List
A1: Master Shopping List — 19 People · 6 Bear Cans | July 25–30, 2026
A2: 🟡 Yellow = bulk buy (Costco/Amazon) | 🟠 Orange = adult supplement | Group Total = 3*(Scout 3) + 1*(Scout 4) + 2*(Adult 3)
A3: ☐ | B3: Food Item | C3: Phase 1 Qty (Scout 3 Can) | D3: Phase 1 Qty (Scout 4 Can) | E3: Phase 1 Qty (Adult 3 Can) | F3: Phase 2 Qty (Scout 3 Can) | G3: Phase 2 Qty (Scout 4 Can) | H3: Phase 2 Qty (Adult 3 Can) | I3: Group Total (6 Days Packs) | J3: $/Unit | K3: Scout 3 Cost (6 Days) | L3: Scout 4 Cost (6 Days) | M3: Adult 3 Cost (6 Days) | N3: Group Total $ | O3: oz/unit | P3: Group ozs | Q3: Where to Buy
A4: ☐ | B4: 88 Acres Seed + Oat Bars (allergy scout) | C4: 0 | D4: 0 | E4: 0 | F4: 0 | G4: 0 | H4: 0 | I4: 6 | J4: 2.4 | K4: =(C4+F4)*J4 | L4: =(D4+G4)*J4 | M4: =(E4+H4)*J4 | N4: =I4*J4 | O4: 1.4 | P4: =I4*O4 | Q4: Allergy scout snacks swap
A5: ☐ | B5: Adults: own coffee / tea | C5: 0 | D5: 0 | E5: 6 | F5: 0 | G5: 0 | H5: 9 | I5: =3*(C5+F5)+1*(D5+G5)+2*(E5+H5) | J5: 0 | K5: =(C5+F5)*J5 | L5: =(D5+G5)*J5 | M5: =(E5+H5)*J5 | N5: =I5*J5 | O5: 0 | P5: =I5*O5 | Q5: Adults only ★
A6: ☐ | B6: Backpacker's Pantry – Crème Brûlée | C6: 4 | D6: 4 | E6: 4 | F6: 2 | G6: 2 | H6: 2 | I6: =3*(C6+F6)+1*(D6+G6)+2*(E6+H6) | J6: 8.99 | K6: =(C6+F6)*J6 | L6: =(D6+G6)*J6 | M6: =(E6+H6)*J6 | N6: =I6*J6 | O6: 2.26 | P6: =I6*O6 | Q6: Buddy-pair shares pouch
A7: ☐ | B7: Banana Chips (1 oz) | C7: 3 | D7: 4 | E7: 3 | F7: 3 | G7: 4 | H7: 3 | I7: =3*(C7+F7)+1*(D7+G7)+2*(E7+H7) | J7: 0.45 | K7: =(C7+F7)*J7 | L7: =(D7+G7)*J7 | M7: =(E7+H7)*J7 | N7: =I7*J7 | O7: 1 | P7: =I7*O7 | Q7: Nut-free ✓
A8: ☐ | B8: Chicken of the Sea Shredded Chicken Pouch | C8: 3 | D8: 4 | E8: 3 | F8: 3 | G8: 4 | H8: 3 | I8: =3*(C8+F8)+1*(D8+G8)+2*(E8+H8) | J8: 2.29 | K8: =(C8+F8)*J8 | L8: =(D8+G8)*J8 | M8: =(E8+H8)*J8 | N8: =I8*J8 | O8: 2.5 | P8: =I8*O8 | Q8: No cook; nut-free ✓
A9: ☐ | B9: Clif Bar – Crunchy PB | C9: 6 | D9: 8 | E9: 6 | F9: 6 | G9: 8 | H9: 6 | I9: =3*(C9+F9)+1*(D9+G9)+2*(E9+H9) | J9: 1.29 | K9: =(C9+F9)*J9 | L9: =(D9+G9)*J9 | M9: =(E9+H9)*J9 | N9: =I9*J9 | O9: 2.4 | P9: =I9*O9 | Q9: Lunch snack; ⚠ NUT
A10: ☐ | B10: Clif Builder's Bar (adult supplement) | C10: 0 | D10: 0 | E10: 3 | F10: 0 | G10: 0 | H10: 3 | I10: =3*(C10+F10)+1*(D10+G10)+2*(E10+H10) | J10: 2.17 | K10: =(C10+F10)*J10 | L10: =(D10+G10)*J10 | M10: =(E10+H10)*J10 | N10: =I10*J10 | O10: 2.4 | P10: =I10*O10 | Q10: Adults only ★; ⚠ NUT
A11: ☐ | B11: Columbus Hard Salami (sliced packet) | C11: 3 | D11: 4 | E11: 3 | F11: 3 | G11: 4 | H11: 3 | I11: =3*(C11+F11)+1*(D11+G11)+2*(E11+H11) | J11: 2.99 | K11: =(C11+F11)*J11 | L11: =(D11+G11)*J11 | M11: =(E11+H11)*J11 | N11: =I11*J11 | O11: 2 | P11: =I11*O11 | Q11: Lunch; 1/person; nut-free
A12: ☐ | B12: Gatorade Powder Pack | C12: 12 | D12: 16 | E12: 12 | F12: 12 | G12: 16 | H12: 12 | I12: =3*(C12+F12)+1*(D12+G12)+2*(E12+H12) | J12: 0.38 | K12: =(C12+F12)*J12 | L12: =(D12+G12)*J12 | M12: =(E12+H12)*J12 | N12: =I12*J12 | O12: 1.23 | P12: =I12*O12 | Q12: Electrolytes
A13: ☐ | B13: Honey Stinger Gold Waffle (allergy scout) | C13: 0 | D13: 0 | E13: 0 | F13: 0 | G13: 0 | H13: 0 | I13: 5 | J13: 1.09 | K13: =(C13+F13)*J13 | L13: =(D13+G13)*J13 | M13: =(E13+H13)*J13 | N13: =I13*J13 | O13: 1 | P13: =I13*O13 | Q13: Allergy scout dessert swap
A14: ☐ | B14: Idahoan Mashed Potatoes – Butter & Herb | C14: 3 | D14: 4 | E14: 3 | F14: 3 | G14: 4 | H14: 3 | I14: =3*(C14+F14)+1*(D14+G14)+2*(E14+H14) | J14: 0.98 | K14: =(C14+F14)*J14 | L14: =(D14+G14)*J14 | M14: =(E14+H14)*J14 | N14: =I14*J14 | O14: 1 | P14: =I14*O14 | Q14: Dinner side
A15: ☐ | B15: Justin's Classic PB Squeeze Pack | C15: 6 | D15: 8 | E15: 6 | F15: 6 | G15: 8 | H15: 6 | I15: =3*(C15+F15)+1*(D15+G15)+2*(E15+H15) | J15: 1.49 | K15: =(C15+F15)*J15 | L15: =(D15+G15)*J15 | M15: =(E15+H15)*J15 | N15: =I15*J15 | O15: 1.15 | P15: =I15*O15 | Q15: Lunch side; ⚠ NUT
A16: ☐ | B16: Justin's Dark Chocolate Peanut Butter Cups | C16: 3 | D16: 4 | E16: 3 | F16: 3 | G16: 4 | H16: 3 | I16: =3*(C16+F16)+1*(D16+G16)+2*(E16+H16) | J16: 1.49 | K16: =(C16+F16)*J16 | L16: =(D16+G16)*J16 | M16: =(E16+H16)*J16 | N16: =I16*J16 | O16: 1.41 | P16: =I16*O16 | Q16: 1 packet/person; ⚠ NUT
A17: ☐ | B17: Justin's PB Squeeze (adult supplement) | C17: 0 | D17: 0 | E17: 3 | F17: 0 | G17: 0 | H17: 3 | I17: =3*(C17+F17)+1*(D17+G17)+2*(E17+H17) | J17: 1.49 | K17: =(C17+F17)*J17 | L17: =(D17+G17)*J17 | M17: =(E17+H17)*J17 | N17: =I17*J17 | O17: 1.15 | P17: =I17*O17 | Q17: Adults only ★; ⚠ NUT
A18: ☐ | B18: Kind – Caramel Almond & Peanut Bar | C18: 3 | D18: 4 | E18: 3 | F18: 3 | G18: 4 | H18: 3 | I18: =3*(C18+F18)+1*(D18+G18)+2*(E18+H18) | J18: 1.59 | K18: =(C18+F18)*J18 | L18: =(D18+G18)*J18 | M18: =(E18+H18)*J18 | N18: =I18*J18 | O18: 1.4 | P18: =I18*O18 | Q18: ⚠ NUT: swap → 88 Acres bar
A19: ☐ | B19: Kind – Dark Choc Nuts & Sea Salt Bar | C19: 3 | D19: 4 | E19: 3 | F19: 3 | G19: 4 | H19: 3 | I19: =3*(C19+F19)+1*(D19+G19)+2*(E19+H19) | J19: 1.04 | K19: =(C19+F19)*J19 | L19: =(D19+G19)*J19 | M19: =(E19+H19)*J19 | N19: =I19*J19 | O19: 1.4 | P19: =I19*O19 | Q19: ⚠ NUT: swap → 88 Acres bar
A20: ☐ | B20: Kind – Peanut Butter Dark Chocolate Bar | C20: 3 | D20: 4 | E20: 3 | F20: 3 | G20: 4 | H20: 3 | I20: =3*(C20+F20)+1*(D20+G20)+2*(E20+H20) | J20: 1.04 | K20: =(C20+F20)*J20 | L20: =(D20+G20)*J20 | M20: =(E20+H20)*J20 | N20: =I20*J20 | O20: 1.4 | P20: =I20*O20 | Q20: ⚠ NUT: swap → 88 Acres bar
A21: ☐ | B21: Krave Sea Salt Original Beef Jerky | C21: 9 | D21: 12 | E21: 9 | F21: 9 | G21: 12 | H21: 9 | I21: =3*(C21+F21)+1*(D21+G21)+2*(E21+H21) | J21: 2.19 | K21: =(C21+F21)*J21 | L21: =(D21+G21)*J21 | M21: =(E21+H21)*J21 | N21: =I21*J21 | O21: 1.48 | P21: =I21*O21 | Q21: Safe for nut allergy ✓
A22: ☐ | B22: MET-Rx Big100 – Super Cookie Crunch | C22: 3 | D22: 4 | E22: 3 | F22: 6 | G22: 8 | H22: 6 | I22: =3*(C22+F22)+1*(D22+G22)+2*(E22+H22) | J22: 2.19 | K22: =(C22+F22)*J22 | L22: =(D22+G22)*J22 | M22: =(E22+H22)*J22 | N22: =I22*J22 | O22: 3.53 | P22: =I22*O22 | Q22: Bkfst · ⚠ NUT
A23: ☐ | B23: Mission Street Taco Flour Tortillas | C23: 30 | D23: 40 | E23: 30 | F23: 24 | G23: 32 | H23: 24 | I23: =3*(C23+F23)+1*(D23+G23)+2*(E23+H23) | J23: 0.25 | K23: =(C23+F23)*J23 | L23: =(D23+G23)*J23 | M23: =(E23+H23)*J23 | N23: =I23*J23 | O23: 0.5 | P23: =I23*O23 | Q23: 2/person; nut-free ✓
A24: ☐ | B24: Once Again Organic Sunflower Butter Squeeze | C24: 0 | D24: 0 | E24: 0 | F24: 0 | G24: 0 | H24: 0 | I24: 4 | J24: 1.5 | K24: =(C24+F24)*J24 | L24: =(D24+G24)*J24 | M24: =(E24+H24)*J24 | N24: =I24*J24 | O24: 1.15 | P24: =I24*O24 | Q24: Allergy scout PB swap
A25: ☐ | B25: Peak Refuel – Beef Pasta Marinara | C25: 4 | D25: 6 | E25: 6 | F25: 2 | G25: 3 | H25: 3 | I25: =3*(C25+F25)+1*(D25+G25)+2*(E25+H25) | J25: 7.49 | K25: =(C25+F25)*J25 | L25: =(D25+G25)*J25 | M25: =(E25+H25)*J25 | N25: =I25*J25 | O25: 3.2 | P25: =I25*O25 | Q25: Sat dinner (1.5 svgs/pouch)
A26: ☐ | B26: Peak Refuel – Beef Stroganoff | C26: 2 | D26: 3 | E26: 3 | F26: 2 | G26: 3 | H26: 3 | I26: =3*(C26+F26)+1*(D26+G26)+2*(E26+H26) | J26: 7.49 | K26: =(C26+F26)*J26 | L26: =(D26+G26)*J26 | M26: =(E26+H26)*J26 | N26: =I26*J26 | O26: 3.5 | P26: =I26*O26 | Q26: Sun dinner (1.5 svgs/pouch)
A27: ☐ | B27: Peak Refuel – Fudge Brownie Bites | C27: 2 | D27: 2 | E27: 2 | F27: 2 | G27: 2 | H27: 2 | I27: =3*(C27+F27)+1*(D27+G27)+2*(E27+H27) | J27: 4.99 | K27: =(C27+F27)*J27 | L27: =(D27+G27)*J27 | M27: =(E27+H27)*J27 | N27: =I27*J27 | O27: 1.5 | P27: =I27*O27 | Q27: Buddy-pair shares pouch
A28: ☐ | B28: ProBar Meal – Oatmeal Chocolate Chip | C28: 6 | D28: 8 | E28: 6 | F28: 6 | G28: 8 | H28: 6 | I28: =3*(C28+F28)+1*(D28+G28)+2*(E28+H28) | J28: 2.99 | K28: =(C28+F28)*J28 | L28: =(D28+G28)*J28 | M28: =(E28+H28)*J28 | N28: =I28*J28 | O28: 3 | P28: =I28*O28 | Q28: Lunch · ⚠ NUT (cashews)
A29: ☐ | B29: Swiss Miss Hot Chocolate | C29: 48 | D29: 64 | E29: 0 | F29: 42 | G29: 56 | H29: 0 | I29: =3*(C29+F29)+1*(D29+G29)+2*(E29+H29) | J29: 0.38 | K29: =(C29+F29)*J29 | L29: =(D29+G29)*J29 | M29: =(E29+H29)*J29 | N29: =I29*J29 | O29: 0.73 | P29: =I29*O29 | Q29: Scouts only (2 packets/person)
A30: ☐ | B30: Tillamook Cheddar Cheese Packets | C30: 18 | D30: 24 | E30: 18 | F30: 12 | G30: 16 | H30: 12 | I30: =3*(C30+F30)+1*(D30+G30)+2*(E30+H30) | J30: 0.75 | K30: =(C30+F30)*J30 | L30: =(D30+G30)*J30 | M30: =(E30+H30)*J30 | N30: =I30*J30 | O30: 0.7 | P30: =I30*O30 | Q30: 2/person; nut-free ✓
A31: ☐ | B31: Trader Joe's Dried Mango Slices (1 oz) | C31: 3 | D31: 4 | E31: 3 | F31: 3 | G31: 4 | H31: 3 | I31: =3*(C31+F31)+1*(D31+G31)+2*(E31+H31) | J31: 0.55 | K31: =(C31+F31)*J31 | L31: =(D31+G31)*J31 | M31: =(E31+H31)*J31 | N31: =I31*J31 | O31: 1 | P31: =I31*O31 | Q31: TJ's — Sat snack · nut-free ✓
A32: ☐ | B32: Wasa Crisp'n Light Crackerbread | C32: 3 | D32: 4 | E32: 3 | F32: 3 | G32: 4 | H32: 3 | I32: =3*(C32+F32)+1*(D32+G32)+2*(E32+H32) | J32: 0.5 | K32: =(C32+F32)*J32 | L32: =(D32+G32)*J32 | M32: =(E32+H32)*J32 | N32: =I32*J32 | O32: 1 | P32: =I32*O32 | Q32: Lunch side
B33: Grand Total | K33: =SUM(K4:K32) | L33: =SUM(L4:L32) | M33: =SUM(M4:M32) | N33: =SUM(N4:N32) | P33: =SUM(P4:P32)

Sheet Packing List
A1: EMIGRANT WILDERNESS — BEAR CAN PACKING LIST · July 25–30, 2026
A2: Check off each item as you pack. ★ = adult supplement. Qty = items per bear can type.
A4: Packed | B4: Meal | C4: Item | D4: Scout Can (3 ppl) Qty | E4: Scout Can (4 ppl) Qty | F4: Adult Can (3 ppl) Qty | G4: Notes
A5: PHASE 1 — INITIAL CARRY (DAYS 1–3) — PACK AT TRAILHEAD
A6: SATURDAY JUL 25 — DAY 1
A7: ☐ | B7: SNACKS | C7: Kind – Peanut Butter Dark Chocolate Bar | D7: 3 | E7: 4 | F7: 3 | G7: hip-belt pocket; ⚠ NUT
A8: ☐ | B8: SNACKS | C8: Kind – Caramel Almond & Peanut Bar | D8: 3 | E8: 4 | F8: 3 | G8: hip-belt pocket; ⚠ NUT
A9: ☐ | B9: SNACKS | C9: Krave Sea Salt Original Beef Jerky | D9: 3 | E9: 4 | F9: 3 | G9: hip-belt pocket; nut-free
A10: ☐ | B10: SNACKS | C10: Gatorade Powder Pack | D10: 3 | E10: 4 | F10: 3 | G10: hip-belt pocket; electrolytes
A11: ☐ | B11: SNACKS | C11: Trader Joe's Dried Mango Slices (1 oz) | D11: 3 | E11: 4 | F11: 3 | G11: hip-belt pocket; nut-free
A12: ☐ | B12: LUNCH | C12: ProBar Meal – Oatmeal Chocolate Chip | D12: 3 | E12: 4 | F12: 3 | G12: no cook; ⚠ NUT
A13: ☐ | B13: DINNER | C13: Peak Refuel – Beef Pasta Marinara | D13: 2 | E13: 3 | F13: 3 | G13: hot · 1.5 svgs/pouch
A14: ☐ | B14: DINNER | C14: Flour Tortillas | D14: 6 | E14: 8 | F14: 6 | G14: dinner wraps + side
A15: ☐ | B15: DINNER | C15: Tillamook Cheddar Cheese Packets | D15: 6 | E15: 8 | F15: 6 | G15: dinner side
A16: ☐ | B16: DINNER | C16: Swiss Miss Hot Chocolate | D16: 6 | E16: 8 | F16: 0 | G16: scouts only
A17: ☐ | B17: DESSERT | C17: Backpacker's Pantry Crème Brûlée | D17: 2 | E17: 2 | F17: 2 | G17: hot · buddy-pair shares pouch
A18: ☐ | B18: DESSERT | C18: Swiss Miss Hot Chocolate | D18: 6 | E18: 8 | F18: 0 | G18: scouts only
A19: SUNDAY JUL 26 — DAY 2
A20: ☐ | B20: BREAKFAST | C20: MET-Rx Big100 – Super Cookie Crunch | D20: 3 | E20: 4 | F20: 3 | G20: grab & go; ⚠ NUT
A21: ☐ | B21: BREAKFAST | C21: Swiss Miss Hot Chocolate | D21: 6 | E21: 8 | F21: 0 | G21: scouts only
A22: ☐ | B22: BREAKFAST | C22: Adults: own coffee / tea | D22: 0 | E22: 0 | F22: 3 | G22: adults only ★
A23: ☐ | B23: SNACKS | C23: Krave Sea Salt Original Beef Jerky | D23: 3 | E23: 4 | F23: 3 | G23: hip-belt pocket; nut-free
A24: ☐ | B24: SNACKS | C24: Kind – Dark Choc Nuts & Sea Salt Bar | D24: 3 | E24: 4 | F24: 3 | G24: hip-belt pocket; ⚠ NUT
A25: ☐ | B25: SNACKS | C25: Gatorade Powder Pack | D25: 6 | E25: 8 | F25: 6 | G25: ×2/person; climb day
A26: ☐ | B26: SNACKS | C26: Banana Chips (1 oz) | D26: 3 | E26: 4 | F26: 3 | G26: nut-free
A27: ☐ | B27: LUNCH | C27: Chicken of the Sea Shredded Chicken Pouch | D27: 3 | E27: 4 | F27: 3 | G27: no cook; nut-free
A28: ☐ | B28: LUNCH | C28: Flour Tortillas | D28: 6 | E28: 8 | F28: 6 | G28: lunch wraps
A29: ☐ | B29: LUNCH | C29: Tillamook Cheddar Cheese Packets | D29: 3 | E29: 4 | F29: 3 | G29: lunch side
A30: ☐ | B30: LUNCH | C30: Clif Bar – Crunchy PB | D30: 3 | E30: 4 | F30: 3 | G30: lunch snack; ⚠ NUT
A31: ☐ | B31: LUNCH | C31: Justin's Classic PB Squeeze Pack | D31: 3 | E31: 4 | F31: 3 | G31: lunch side; ⚠ NUT
... A39: ☐ | B39: DESSERT | C39: Swiss Miss Hot Chocolate | D39: 6 | E39: 8 | F39: 0 | G39: scouts only
A40: MONDAY JUL 27 — DAY 3
A41: ☐ | B41: BREAKFAST | C41: ProBar Meal – Oatmeal Chocolate Chip | D41: 3 | E41: 4 | F41: 3 | G41: grab & go; ⚠ NUT (cashews)
A42: ☐ | B42: BREAKFAST | C42: Swiss Miss Hot Chocolate | D42: 6 | E42: 8 | F42: 0 | G42: scouts only
A43: ☐ | B43: BREAKFAST | C43: Adults: own coffee / tea | D43: 0 | E43: 0 | F43: 3 | G43: adults only ★
A44: ☐ | B44: SNACKS | C44: Krave Sea Salt Original Beef Jerky | D44: 3 | E44: 4 | F44: 3 | G44: hip-belt pocket; nut-free
A45: ☐ | B45: SNACKS | C45: Clif Bar – Crunchy PB | D45: 3 | E45: 4 | F45: 3 | G45: hip-belt pocket; ⚠ NUT
A46: ☐ | B46: SNACKS | C46: Gatorade Powder Pack | D46: 3 | E46: 4 | F46: 3 | G46: hip-belt pocket; electrolytes
A47: ☐ | B47: SNACKS | C47: Peak Refuel – Fudge Brownie Bites | D47: 2 | E47: 2 | F47: 2 | G47: morale afternoon snack; nut-free
A48: ☐ | B48: LUNCH | C48: Columbus Hard Salami (packet) | D48: 3 | E48: 4 | F48: 3 | G48: no cook; nut-free
...

Sheet Nut Allergy — Scout Pack
A1: Nut Allergy Accommodation — Individual Scout Carry Pack (6 Days)
A2: Pre-pack all items in a labelled zip-lock or dry bag for this scout. They carry it personally and swap at each nut-item moment. Main canisters are UNCHANGED.
A4: Day | B4: Meal | C4: Remove (has nuts) | D4: Nuts in it | E4: Replace with | F4: Why safe | G4: kcal | H4: Where to buy
A5: Sat Jul 25 | B5: Snacks | C5: Kind PB Dark Choc Bar | D5: Peanuts, almonds | E5: 88 Acres Dark Choc Sea Salt Seed + Oat Bar | F5: Dedicated nut-free bakery. Free from top 9. | G5: 150 | H5: Amazon / 88acres.com
A6: Sat Jul 25 | B6: Snacks | C6: Kind – Caramel Almond & Peanut Bar | D6: Almonds, peanuts | E6: 88 Acres Cinnamon Maple Seed + Oat Bar | F6: Same nut-free facility. | G6: 150 | H6: Amazon / 88acres.com
A7: Sat Jul 25 | B7: Dessert | C7: BP Crème Brûlée | D7: Check label - may contain cashews | E7: Honey Stinger Gold Waffle (contingency) | F7: Honey Stinger: simple ingredients, no nuts. | G7: 160 | H7: REI / Amazon
A8: Sun Jul 26 | B8: Breakfast | C8: MET-Rx Big100 Super Cookie Crunch | D8: Peanuts, almonds, tree nuts | E8: No Nuts! Chocolate Chip Protein Bar | F8: Certified 100% nut-free facility. 12g protein. | G8: 185 | H8: Amazon / gononuts.com
A9: Sun Jul 26 | B9: Snacks | C9: Kind – Dark Choc Nuts & Sea Salt Bar | D9: Almonds, peanuts, cashews | E9: 88 Acres bar (any flavor) | F9: Same nut-free facility. | G9: 150 | H9: Amazon / 88acres.com
A10: Sun Jul 26 | B10: Lunch | C10: Clif Bar – Crunchy PB | D10: Peanuts | E10: Clif Bar – Chocolate Chip | F10: Clif Chocolate Chip: no nuts in ingredients. | G10: 250 | H10: Add to main Costco order
A11: Sun Jul 26 | B11: Lunch | C11: Justin's Classic PB Squeeze Pack | D11: Peanuts | E11: Once Again Sunflower Butter Squeeze Pack | F11: Peanut-free facility. Free from top 9. | G11: 200 | H11: Amazon
A12: Sun Jul 26 | B12: Dessert | C12: Justin's Dark Choc PB Cups | D12: Peanuts, almonds | E12: Honey Stinger Gold Waffle or Enjoy Life Choc | F12: No nuts. Enjoy Life: top-14 free. | G12: 160 | H12: REI / Amazon
A13: Mon Jul 27 | B13: Breakfast | C13: ProBar Meal – Oatmeal Chocolate Chip | D13: Cashews | E13: No Nuts! Cinnamon Roll or Caramel Mocha | F13: Same certified nut-free facility. | G13: 185 | H13: Amazon / gononuts.com
A14: Mon Jul 27 | B14: Snacks | C14: Clif Bar – Crunchy PB | D14: Peanuts | E14: Clif Bar – Chocolate Chip | F14: Clif Chocolate Chip: no nuts in ingredients. | G14: 250 | H14: Add to main Costco order
A15: Mon Jul 27 | B15: Lunch | C15: Justin's Classic PB Squeeze Pack | D15: Peanuts | E15: Once Again Sunflower Butter Squeeze Pack | F15: Peanut-free facility. Free from top 9. | G15: 200 | H15: Amazon
A16: Tue Jul 28 | B16: Breakfast | C16: MET-Rx Big100 Super Cookie Crunch | D16: Peanuts, almonds, tree nuts | E16: No Nuts! Chocolate Chip Protein Bar | F16: Certified 100% nut-free facility. | G16: 185 | H16: Amazon
... A27: Thu Jul 30 | B27: Lunch | C27: Justin's Classic PB Squeeze Pack | D27: Peanuts | E27: Once Again Sunflower Butter Squeeze Pack | F27: Peanut-free facility. | G27: 200 | H27: Amazon
